Workbook

Sheet Asset Register
A1: Asset Register — NIST CSF 2.0 ID.AM (source: 01-asset-inventory.md)
A2: Asset ID (AST-xxx) is the key referenced by the Protect / Detect sheets. Yellow cells are inputs. Rows up to AST-100 are pre-numbered for future additions.
A4: Asset ID | B4: Source ID | C4: Layer | D4: Category | E4: Asset Name | F4: Description | G4: C | H4: I | I4: A | J4: Priority | K4: Control / Owner | L4: Related Findings | M4: Notes
A5: AST-001 | B5: H-01 | C5: Hardware | D5: Device | E5: MacBook Air (M4) | F5: Primary laptop; holds all work and study files | G5: High | H5: High | I5: High | J5: Critical | K5: Self | L5: F4, F5
A6: AST-002 | B6: H-02 | C6: Hardware | D6: Device | E6: iPhone 14 | F6: Primary phone; 2FA device for most accounts; Apple Pay wallet | G6: High | H6: High | I6: High | J6: Critical | K6: Self | L6: F1, F2, F5
A7: AST-003 | B7: H-03 | C7: Hardware | D7: Device | E7: iPad | F7: Study device (note-taking, reading) | G7: Medium | H7: Medium | I7: Medium | J7: Medium | K7: Self | L7: F2, F5
A8: AST-004 | B8: H-04 | C8: Hardware | D8: Device | E8: eSIM profile | F8: Binds the phone number to the device; foundation of SMS-based 2FA | G8: High | H8: High | I8: High | J8: Critical | K8: Self | L8: F3
A9: AST-005 | B9: H-05 | C9: Hardware | D9: Network | E9: Home Wi-Fi network | F9: Landlord-provided; password shared with roommates; router admin access unknown | G9: Medium | H9: Low | I9: Medium | J9: High | K9: Third party | L9: F5
A10: AST-006 | B10: A-F01 | C10: Account | D10: Financial | E10: Primary US bank | F10: Checking and savings; main US banking | G10: High | H10: High | I10: High | J10: Critical | K10: Third party
A11: AST-007 | B11: A-F02 | C11: Account | D11: Financial | E11: International transfer service | F11: JP <-> US transfers; stores bank details in both countries | G11: High | H11: High | I11: High | J11: Critical | K11: Third party
A12: AST-008 | B12: A-F03 | C12: Account | D12: Financial | E12: Credit card portal (x1) | F12: US-issued credit card | G12: High | H12: High | I12: Medium | J12: Critical | K12: Third party
A13: AST-009 | B13: A-F04 | C13: Account | D13: Financial | E13: Debit card portals (x4) | F13: US-issued debit cards | G13: High | H13: High | I13: Medium | J13: High | K13: Third party
A14: AST-010 | B14: A-F05 | C14: Account | D14: Financial | E14: Apple Pay | F14: Holds all 5 payment cards; depends on a single iPhone | G14: High | H14: High | I14: Medium | J14: Critical | K14: Third party | L14: F1, F2
A15: AST-011 | B15: A-F06 | C15: Account | D15: Financial | E15: P2P payment app | F15: Linked to bank account | G15: Medium | H15: High | I15: Medium | J15: High | K15: Third party
A16: AST-012 | B16: A-F07 | C16: Account | D16: Financial | E16: Bank-integrated transfer service | F16: Direct bank-to-bank transfers | G16: Medium | H16: High | I16: Medium | J16: High | K16: Third party
A17: AST-013 | B17: A-I01 | C17: Account | D17: Identity & Email | E17: Gmail (primary) | F17: Password-reset destination for most services | G17: High | H17: High | I17: High | J17: Critical | K17: Third party
A18: AST-014 | B18: A-I02 | C18: Account | D18: Identity & Email | E18: Gmail (secondary) | F18: Purpose to be reviewed | G18: High | H18: High | I18: Medium | J18: High | K18: Third party
A19: AST-015 | B19: A-I03 | C19: Account | D19: Identity & Email | E19: College email | F19: Institution-issued; official academic communication | G19: High | H19: Medium | I19: High | J19: High | K19: Institution
A20: AST-016 | B20: A-I04 | C20: Account | D20: Identity & Email | E20: Outlook account | F20: Purpose to be reviewed | G20: Medium | H20: Medium | I20: Low | J20: Medium | K20: Third party
A21: AST-017 | B21: A-I05 | C21: Account | D21: Identity & Email | E21: Apple ID | F21: Controls iPhone, iPad, MacBook, iCloud, and Apple Pay | G21: High | H21: High | I21: High | J21: Critical | K21: Third party | L21: F1, F2
A22: AST-018 | B22: A-I06 | C22: Account | D22: Identity & Email | E22: Google Account | F22: Tied to primary Gmail; controls Drive, Photos, YouTube | G22: High | H22: High | I22: High | J22: Critical | K22: Third party
A23: AST-019 | B23: A-I07 | C23: Account | D23: Identity & Email | E23: Microsoft 365 (institution-provided) | F23: Managed by the college, not by me | G23: Medium | H23: Medium | I23: Medium | J23: Medium | K23: Institution
A24: AST-020 | B24: A-E01 | C24: Account | D24: Education & Learning | E24: College student portal | F24: Grades, enrollment, financial aid, transcripts | G24: High | H24: High | I24: High | J24: Critical | K24: Institution
A25: AST-021 | B25: A-E02 | C25: Account | D25: Education & Learning | E25: Learning management system | F25: Coursework and submissions | G25: Medium | H25: High | I25: High | J25: High | K25: Institution
A26: AST-022 | B26: A-E03 | C26: Account | D26: Education & Learning | E26: English proficiency test account | F26: Official test scores and score reporting | G26: Medium | H26: High | I26: Low | J26: Medium | K26: Third party
A27: AST-023 | B27: A-E04 | C27: Account | D27: Education & Learning | E27: Programming learning platform | F27: Beginner coding courses | G27: Low | H27: Low | I27: Low | J27: Low | K27: Third party
A28: AST-024 | B28: A-E05 | C28: Account | D28: Education & Learning | E28: TryHackMe | F28: Security learning progress | G28: Low | H28: Medium | I28: Low | J28: Low | K28: Third party
A29: AST-025 | B29: A-E06 | C29: Account | D29: Education & Learning | E29: Language learning app | F29: Casual practice | G29: Low | H29: Low | I29: Low | J29: Low | K29: Third party
A30: AST-026 | B30: A-E07 | C30: Account | D30: Education & Learning | E30: ChatGPT | F30: Conversation history may contain personal context | G30: Medium | H30: Low | I30: Low | J30: Medium | K30: Third party
A31: AST-027 | B31: A-E08 | C31: Account | D31: Education & Learning | E31: Claude | F31: Conversations include career strategy, resume drafts, project planning | G31: Medium | H31: Low | I31: Low | J31: Medium | K31: Third party
A32: AST-028 | B32: A-E09 | C32: Account | D32: Education & Learning | E32: Gemini | F32: Limited usage | G32: Low | H32: Low | I32: Low | J32: Low | K32: Third party
A33: AST-029 | B33: A-E10 | C33: Account | D33: Education & Learning | E33: Notion (account) | F33: Study notes; may contain career information | G33: High | H33: High | I33: Medium | J33: High | K33: Third party
... A46: AST-042 | B46: A-S06 | C46: Account | D46: Social Media | E46: YouTube | F46: Accessed through Google Account (A-I06) | G46: Low | H46: Low | I46: Low | J46: Low | K46: Third party
A47: AST-043 | B47: A-U01 | C47: Account | D47: Utilities & Life Services | E47: Mobile carrier account | F47: Controls the phone number -> SMS 2FA foundation; SIM-swap target | G47: High | H47: High | I47: High | J47: Critical | K47: Third party | L47: F1, F3
A48: AST-044 | B48: A-U02 | C48: Account | D48: Utilities & Life Services | E48: Student health insurance | F48: School-provided | G48: Medium | H48: Medium | I48: Low | J48: Medium | K48: Institution
A49: AST-045 | B49: A-X01 | C49: Account | D49: Entertainment & Shopping | E49: Amazon | F49: Purchase history, saved addresses, saved payment cards | G49: Medium | H49: Medium | I49: Low | J49: Medium | K49: Third party
A50: AST-046 | B50: D-L01 | C50: Data | D50: Local (MacBook) | E50: Job-hunting materials | F50: Resumes, application essays, motivation letters (multiple versions) | G50: High | H50: High | I50: Medium | J50: Critical | K50: Self
A51: AST-047 | B51: D-L02 | C51: Data | D51: Local (MacBook) | E51: Client project materials | F51: Proposal and prototype code for an external project | G51: High | H51: Medium | I51: Low | J51: High | K51: Self
A52: AST-048 | B52: D-L03 | C52: Data | D52: Local (MacBook) | E52: Academic files | F52: Coursework, notes, textbook PDFs | G52: Medium | H52: High | I52: Medium | J52: High | K52: Self
A53: AST-049 | B53: D-L04 | C53: Data | D53: Local (MacBook) | E53: Personal ID scans | F53: Passport, visa, and SSN-related documents | G53: Critical | H53: Critical | I53: Low | J53: Critical | K53: Self
...

Sheet Protect Assessment
A1: Protect (PR) Assessment — NIST CSF 2.0 (asset x subcategory matrix)
A2: One row per asset (= 01-asset-inventory.md). Set each subcategory cell to a Status; N/A = not applicable to this asset (see Guide). Grey = formulas. Your original text is carried over verbatim; blue column = reviewer suggestions only.
A4: Asset ID | B4: Source ID | C4: Asset Name | D4: Category | E4: Priority | F4: PR.AA-01 Credentials | G4: PR.AA-03 Authentication | H4: PR.AA-05 Access review | I4: PR.DS-01 Data at rest | J4: PR.DS-02 Data in transit | K4: PR.DS-11 Backup | L4: PR.PS-01 Configuration | M4: PR.IR-01 Network protection | N4: Overall | O4: Assessed | P4: Remaining ?? | Q4: Gaps | R4: Checklist (per subcategory) | S4: Target State | T4: Current State | U4: Risk if Gap | V4: Evidence / Notes | W4: Remediation Action | X4: Related Finding | Y4: Migrated From | Z4: Reviewer Comment
A5: AST-001 | B5: =IF(A5="","",IFERROR(INDEX('Asset Register'!$B:$B,MATCH(A5,'Asset Register'!$A:$A,0)),"")) -> H-01 | C5: =IF(A5="","",IFERROR(INDEX('Asset Register'!$E:$E,MATCH(A5,'Asset Register'!$A:$A,0)),"")) -> MacBook Air (M4) | D5: =IF(A5="","",IFERROR(INDEX('Asset Register'!$D:$D,MATCH(A5,'Asset Register'!$A:$A,0)),"")) -> Device | E5: =IF(A5="","",IFERROR(INDEX('Asset Register'!$J:$J,MATCH(A5,'Asset Register'!$A:$A,0)),"")) -> Critical | F5: Implemented | G5: Partial | H5: Partial | I5: Not Implemented | J5: Not Implemented | K5: Partial | L5: Partial | M5: Partial | N5: =IF(COUNTA(F5:M5)=0,"",IF((COUNTIF(F5:M5,"Implemented")+COUNTIF(F5:M5,"Partial")+COUNTIF(F5:M5,"Not Implemented"))+COUNTIF(F5:M5,"??")=0,"N/A",IF((COUNTIF(F5:M5,"Implemented")+COUNTIF(F5:M5,"Partial")+COUNTIF(F5:M5,"Not Implemented"))=0,"??",IF(COUNTIF(F5:M5,"Implemented")=(COUNTIF(F5:M5,"Implemented")+COUNTIF(F5:M5,"Partial")+COUNTIF(F5:M5,"Not Implemented")),"Implemented",IF(COUNTIF(F5:M5,"Not Implemented")=(COUNTIF(F5:M5,"Implemented")+COUNTIF(F5:M5,"Partial")+COUNTIF(F5:M5,"Not Implemented")),"Not Implemented","Partial"))))) -> Partial | O5: =IF(COUNTA(F5:M5)=0,"",(COUNTIF(F5:M5,"Implemented")+COUNTIF(F5:M5,"Partial")+COUNTIF(F5:M5,"Not Implemented"))) -> 8 | P5: =IF(COUNTA(F5:M5)=0,"",COUNTIF(F5:M5,"??")) -> 0 | Q5: =IF(COUNTA(F5:M5)=0,"",COUNTIF(F5:M5,"Partial")+COUNTIF(F5:M5,"Not Implemented")) -> 7 | R5: AA-03: Unlock method (passcode strength, biometrics) and auto-lock AA-05: Daily use runs as standard user (not admin); guest user disabled DS-01: FileVault full-disk encryption enabled DS-02: Encrypted transport on untrusted networks (VPN / encrypted DNS) DS-11: MacBook backup (Time Machine or equivalent) PS-01: macOS auto-updates, Gatekeeper, SIP, screen-lock timeout IR-01: macOS firewall enabled (stealth mode); sharing services off | S5: AA-03: Strong passcode / password; biometrics ON; auto-lock enabled AA-05: Separate admin account; guest disabled DS-01: FileVault ON; recovery key stored offline (not only in iCloud) DS-02: Trusted VPN or iCloud Private Relay on untrusted networks DS-11: Encrypted Time Machine backup; restore tested PS-01: Auto-updates ON; Gatekeeper/SIP ON; lock <= 5 min IR-01: Firewall + stealth mode ON; unused sharing off | T5: Touch ID is enabled and screen lock is set to five minutes or less. The daily-use account has administrator privileges, while Guest User is disabled. FileVault, automatic updates, and the macOS firewall are enabled. File Sharing is disabled. No Mac backup is configured. VPN / Private Relay is not used. FileVault recovery-key storage, Gatekeeper, SIP, and Firewall Stealth Mode have not yet been verified. | U5: Daily use with administrator privileges increases the impact of malicious or accidental actions. Lack of backup creates a risk of permanent data loss. Unverified recovery and platform-hardening settings may leave additional security gaps, and no additional encrypted transport is used on untrusted networks. | V5: User confirmed Touch ID ON, screen lock within five minutes, daily-use Admin account, Guest User OFF, FileVault ON, automatic updates ON, firewall ON, File Sharing OFF, no backup, and no VPN / Private Relay. FileVault recovery-key storage, Gatekeeper, SIP, and Stealth Mode remain unverified. | W5: Use a standard account for daily activity and keep a separate admin account. Configure an encrypted backup and test restoration. Verify FileVault recovery-key storage, Gatekeeper, SIP, and Stealth Mode. Consider encrypted transport on untrusted networks. | X5: F4, F5 | Y5: PR-025, PR-028, PR-039, PR-043, PR-046, PR-051
A6: AST-002 | B6: =IF(A6="","",IFERROR(INDEX('Asset Register'!$B:$B,MATCH(A6,'Asset Register'!$A:$A,0)),"")) -> H-02 | C6: =IF(A6="","",IFERROR(INDEX('Asset Register'!$E:$E,MATCH(A6,'Asset Register'!$A:$A,0)),"")) -> iPhone 14 | D6: =IF(A6="","",IFERROR(INDEX('Asset Register'!$D:$D,MATCH(A6,'Asset Register'!$A:$A,0)),"")) -> Device | E6: =IF(A6="","",IFERROR(INDEX('Asset Register'!$J:$J,MATCH(A6,'Asset Register'!$A:$A,0)),"")) -> Critical | F6: Partial | G6: Implemented | H6: Partial | I6: Implemented | J6: Not Implemented | K6: Partial | L6: Partial | M6: Implemented | N6: =IF(COUNTA(F6:M6)=0,"",IF((COUNTIF(F6:M6,"Implemented")+COUNTIF(F6:M6,"Partial")+COUNTIF(F6:M6,"Not Implemented"))+COUNTIF(F6:M6,"??")=0,"N/A",IF((COUNTIF(F6:M6,"Implemented")+COUNTIF(F6:M6,"Partial")+COUNTIF(F6:M6,"Not Implemented"))=0,"??",IF(COUNTIF(F6:M6,"Implemented")=(COUNTIF(F6:M6,"Implemented")+COUNTIF(F6:M6,"Partial")+COUNTIF(F6:M6,"Not Implemented")),"Implemented",IF(COUNTIF(F6:M6,"Not Implemented")=(COUNTIF(F6:M6,"Implemented")+COUNTIF(F6:M6,"Partial")+COUNTIF(F6:M6,"Not Implemented")),"Not Implemented","Partial"))))) -> Partial | O6: =IF(COUNTA(F6:M6)=0,"",(COUNTIF(F6:M6,"Implemented")+COUNTIF(F6:M6,"Partial")+COUNTIF(F6:M6,"Not Implemented"))) -> 8 | P6: =IF(COUNTA(F6:M6)=0,"",COUNTIF(F6:M6,"??")) -> 0 | Q6: =IF(COUNTA(F6:M6)=0,"",COUNTIF(F6:M6,"Partial")+COUNTIF(F6:M6,"Not Implemented")) -> 5 | R6: AA-03: Device unlock method (passcode length, Face ID) and Stolen Device Protection DS-01: Device encryption via passcode; Advanced Data Protection for iCloud DS-02: Encrypted transport on untrusted / public Wi-Fi DS-11: Device backup configured and restore tested PS-01: iOS auto-updates, lock-screen access (Control Center, USB Accessories) IR-01: Auto-join of open networks disabled; Private Wi-Fi Address enabled | S6: AA-03: 6+ digit or alphanumeric passcode; Stolen Device Protection ON DS-01: Strong passcode; Advanced Data Protection ON DS-02: Trusted VPN or iCloud Private Relay on public Wi-Fi DS-11: Encrypted backup; restore tested PS-01: Auto-updates ON; lock-screen access minimized IR-01: Auto-join off for public Wi-Fi; private address ON | T6: The iPhone uses a 6-digit passcode with Face ID, and Stolen Device Protection is enabled. Advanced Data Protection and automatic updates are enabled. iCloud Backup is enabled, but restore testing has not been verified. Control Center is unavailable from the Lock Screen, while USB Accessories settings remain unverified | U6: The lack of additional encrypted transport on untrusted networks may leave some network exposure. An untested backup may not provide reliable recovery when needed, and unverified USB accessory settings leave a remaining configuration uncertainty. | V6: User confirmed 6-digit passcode, Face ID, Stolen Device Protection ON, Advanced Data Protection ON, automatic updates ON, iCloud Backup ON, Lock Screen Control Center disabled, public Wi-Fi auto-join OFF, Private Wi-Fi Address ON, and no VPN / Private Relay. | W6: Test recovery from iCloud Backup, verify USB Accessories restrictions while locked, and consider encrypted transport such as a trusted VPN or Private Relay on untrusted networks. | X6: F1, F5 | Y6: PR-021, PR-029, PR-040, PR-047, PR-052
A7: AST-003 | B7: =IF(A7="","",IFERROR(INDEX('Asset Register'!$B:$B,MATCH(A7,'Asset Register'!$A:$A,0)),"")) -> H-03 | C7: =IF(A7="","",IFERROR(INDEX('Asset Register'!$E:$E,MATCH(A7,'Asset Register'!$A:$A,0)),"")) -> iPad | D7: =IF(A7="","",IFERROR(INDEX('Asset Register'!$D:$D,MATCH(A7,'Asset Register'!$A:$A,0)),"")) -> Device | E7: =IF(A7="","",IFERROR(INDEX('Asset Register'!$J:$J,MATCH(A7,'Asset Register'!$A:$A,0)),"")) -> Medium | F7: N/A | G7: Implemented | H7: N/A | I7: Implemented | J7: Not Implemented | K7: Partial | L7: Implemented | M7: Partial | N7: =IF(COUNTA(F7:M7)=0,"",IF((COUNTIF(F7:M7,"Implemented")+COUNTIF(F7:M7,"Partial")+COUNTIF(F7:M7,"Not Implemented"))+COUNTIF(F7:M7,"??")=0,"N/A",IF((COUNTIF(F7:M7,"Implemented")+COUNTIF(F7:M7,"Partial")+COUNTIF(F7:M7,"Not Implemented"))=0,"??",IF(COUNTIF(F7:M7,"Implemented")=(COUNTIF(F7:M7,"Implemented")+COUNTIF(F7:M7,"Partial")+COUNTIF(F7:M7,"Not Implemented")),"Implemented",IF(COUNTIF(F7:M7,"Not Implemented")=(COUNTIF(F7:M7,"Implemented")+COUNTIF(F7:M7,"Partial")+COUNTIF(F7:M7,"Not Implemented")),"Not Implemented","Partial"))))) -> Partial | O7: =IF(COUNTA(F7:M7)=0,"",(COUNTIF(F7:M7,"Implemented")+COUNTIF(F7:M7,"Partial")+COUNTIF(F7:M7,"Not Implemented"))) -> 6 | P7: =IF(COUNTA(F7:M7)=0,"",COUNTIF(F7:M7,"??")) -> 0 | Q7: =IF(COUNTA(F7:M7)=0,"",COUNTIF(F7:M7,"Partial")+COUNTIF(F7:M7,"Not Implemented")) -> 3 | R7: AA-03: Unlock method (passcode strength, biometrics) and auto-lock DS-01: Device passcode set (enables data protection) DS-02: Encrypted transport on untrusted networks DS-11: Device backup configured and restore tested PS-01: iPadOS auto-updates and auto-lock IR-01: Firewall / network exposure settings | S7: AA-03: Strong passcode / password; biometrics ON; auto-lock enabled DS-01: Passcode set; auto-lock enabled DS-02: Trusted VPN or iCloud Private Relay on untrusted networks DS-11: Encrypted backup; restore tested PS-01: Auto-updates ON; auto-lock enabled IR-01: Firewall ON; unused sharing / auto-join off | T7: The iPad uses a 6-digit or longer passcode with biometric authentication enabled. Automatic updates and Auto-Lock are enabled. iCloud Backup is enabled, but restore testing has not been verified. Control Center is not accessible from the Lock Screen, and Private Wi-Fi Address is enabled. | U7: The lack of additional encrypted transport on untrusted networks may leave some network exposure. An untested backup may not provide reliable recovery when needed. Disabling Find My iPad also reduces the ability to locate or remotely manage the device after loss. | V7: User confirmed 6+ digit passcode, biometric authentication ON, automatic updates ON, Auto-Lock ON, iCloud Backup ON, Lock Screen Control Center disabled, Private Wi-Fi Address ON, Find My iPad OFF, and no VPN / Private Relay. Restore testing remains unverified. | W7: Enable Find My iPad, test recovery from iCloud Backup, and consider using trusted encrypted transport on untrusted networks | Y7: PR-030, PR-048
A8: AST-004 | B8: =IF(A8="","",IFERROR(INDEX('Asset Register'!$B:$B,MATCH(A8,'Asset Register'!$A:$A,0)),"")) -> H-04 | C8: =IF(A8="","",IFERROR(INDEX('Asset Register'!$E:$E,MATCH(A8,'Asset Register'!$A:$A,0)),"")) -> eSIM profile | D8: =IF(A8="","",IFERROR(INDEX('Asset Register'!$D:$D,MATCH(A8,'Asset Register'!$A:$A,0)),"")) -> Device | E8: =IF(A8="","",IFERROR(INDEX('Asset Register'!$J:$J,MATCH(A8,'Asset Register'!$A:$A,0)),"")) -> Critical | F8: N/A | G8: Partial | H8: N/A | I8: N/A | J8: N/A | K8: N/A | L8: Not Implemented | M8: N/A | N8: =IF(COUNTA(F8:M8)=0,"",IF((COUNTIF(F8:M8,"Implemented")+COUNTIF(F8:M8,"Partial")+COUNTIF(F8:M8,"Not Implemented"))+COUNTIF(F8:M8,"??")=0,"N/A",IF((COUNTIF(F8:M8,"Implemented")+COUNTIF(F8:M8,"Partial")+COUNTIF(F8:M8,"Not Implemented"))=0,"??",IF(COUNTIF(F8:M8,"Implemented")=(COUNTIF(F8:M8,"Implemented")+COUNTIF(F8:M8,"Partial")+COUNTIF(F8:M8,"Not Implemented")),"Implemented",IF(COUNTIF(F8:M8,"Not Implemented")=(COUNTIF(F8:M8,"Implemented")+COUNTIF(F8:M8,"Partial")+COUNTIF(F8:M8,"Not Implemented")),"Not Implemented","Partial"))))) -> Partial | O8: =IF(COUNTA(F8:M8)=0,"",(COUNTIF(F8:M8,"Implemented")+COUNTIF(F8:M8,"Partial")+COUNTIF(F8:M8,"Not Implemented"))) -> 2 | P8: =IF(COUNTA(F8:M8)=0,"",COUNTIF(F8:M8,"??")) -> 0 | Q8: =IF(COUNTA(F8:M8)=0,"",COUNTIF(F8:M8,"Partial")+COUNTIF(F8:M8,"Not Implemented")) -> 2 | R8: AA-03: Authentication required before the eSIM can be transferred or removed PS-01: SIM/eSIM PIN and eSIM transfer protection | S8: AA-03: eSIM transfer requires device passcode and carrier verification PS-01: SIM PIN enabled | T8: SIM PIN is disabled. Additional authentication requirements for eSIM transfer, reissue, or removal have not been verified. No additional phone-number protection has been confirmed. | U8: Weak or unverified eSIM transfer protection could make unauthorized number reassignment easier, which may affect SMS-based authentication and account recovery. | V8: User confirmed SIM PIN is OFF. Authentication requirements for eSIM transfer or removal remain unverified. | W8: Enable SIM PIN if appropriate and verify the carrier and device requirements for eSIM transfer, reissue, and removal. Enable any available transfer or number-lock protection. | X8: F3 | Y8: PR-049
A9: AST-005 | B9: =IF(A9="","",IFERROR(INDEX('Asset Register'!$B:$B,MATCH(A9,'Asset Register'!$A:$A,0)),"")) -> H-05 | C9: =IF(A9="","",IFERROR(INDEX('Asset Register'!$E:$E,MATCH(A9,'Asset Register'!$A:$A,0)),"")) -> Home Wi-Fi network | D9: =IF(A9="","",IFERROR(INDEX('Asset Register'!$D:$D,MATCH(A9,'Asset Register'!$A:$A,0)),"")) -> Network | E9: =IF(A9="","",IFERROR(INDEX('Asset Register'!$J:$J,MATCH(A9,'Asset Register'!$A:$A,0)),"")) -> High | F9: Not Implemented | G9: N/A | H9: Partial | I9: Implemented | J9: Partial | K9: N/A | L9: Partial | M9: Partial | N9: =IF(COUNTA(F9:M9)=0,"",IF((COUNTIF(F9:M9,"Implemented")+COUNTIF(F9:M9,"Partial")+COUNTIF(F9:M9,"Not Implemented"))+COUNTIF(F9:M9,"??")=0,"N/A",IF((COUNTIF(F9:M9,"Implemented")+COUNTIF(F9:M9,"Partial")+COUNTIF(F9:M9,"Not Implemented"))=0,"??",IF(COUNTIF(F9:M9,"Implemented")=(COUNTIF(F9:M9,"Implemented")+COUNTIF(F9:M9,"Partial")+COUNTIF(F9:M9,"Not Implemented")),"Implemented",IF(COUNTIF(F9:M9,"Not Implemented")=(COUNTIF(F9:M9,"Implemented")+COUNTIF(F9:M9,"Partial")+COUNTIF(F9:M9,"Not Implemented")),"Not Implemented","Partial"))))) -> Partial | O9: =IF(COUNTA(F9:M9)=0,"",(COUNTIF(F9:M9,"Implemented")+COUNTIF(F9:M9,"Partial")+COUNTIF(F9:M9,"Not Implemented"))) -> 6 | P9: =IF(COUNTA(F9:M9)=0,"",COUNTIF(F9:M9,"??")) -> 0 | Q9: =IF(COUNTA(F9:M9)=0,"",COUNTIF(F9:M9,"Partial")+COUNTIF(F9:M9,"Not Implemented")) -> 5 | R9: AA-01: Wi-Fi password strength and who knows it; router admin credentials changed from default AA-05: Who has the Wi-Fi password / admin access; guest network available DS-02: Wi-Fi encryption protocol (WPA2/WPA3) in use PS-01: Router firmware / default settings (or documented as landlord-controlled) IR-01: Router admin control, connected-device visibility, network segmentation | S9: AA-01: Strong Wi-Fi password; admin credentials non-default (or documented as landlord-controlled) AA-05: Access limited to known people; treated as untrusted network DS-02: WPA2-AES or WPA3; treated as untrusted regardless PS-01: Firmware current, or documented as accepted risk IR-01: Treated as untrusted; endpoint controls compensate | T9: The home Wi-Fi uses WPA3, but the Wi-Fi password is weak and shared with other people. The user does not have router administrative access. Router firmware status is unverified, no guest network is available, and network segmentation has not been verified. | U9: A weak shared Wi-Fi password may increase the chance of unauthorized network access. Limited router visibility and unverified firmware or segmentation may leave additional network security gaps. | V9: User confirmed WPA3, a weak shared Wi-Fi password, no router administrative access, no guest network, and unverified firmware and segmentation. | W9: Change the Wi-Fi password to a strong unique passphrase if possible. Treat the network as untrusted, keep endpoint protections enabled, and ask the network owner to verify firmware and segmentation settings. | X9: F5 | Y9: PR-038, PR-050
A10: AST-006 | B10: =IF(A10="","",IFERROR(INDEX('Asset Register'!$B:$B,MATCH(A10,'Asset Register'!$A:$A,0)),"")) -> A-F01 | C10: =IF(A10="","",IFERROR(INDEX('Asset Register'!$E:$E,MATCH(A10,'Asset Register'!$A:$A,0)),"")) -> Primary US bank | D10: =IF(A10="","",IFERROR(INDEX('Asset Register'!$D:$D,MATCH(A10,'Asset Register'!$A:$A,0)),"")) -> Financial | E10: =IF(A10="","",IFERROR(INDEX('Asset Register'!$J:$J,MATCH(A10,'Asset Register'!$A:$A,0)),"")) -> Critical | F10: Implemented | G10: Partial | H10: Partial | I10: N/A | J10: N/A | K10: N/A | L10: N/A | M10: N/A | N10: =IF(COUNTA(F10:M10)=0,"",IF((COUNTIF(F10:M10,"Implemented")+COUNTIF(F10:M10,"Partial")+COUNTIF(F10:M10,"Not Implemented"))+COUNTIF(F10:M10,"??")=0,"N/A",IF((COUNTIF(F10:M10,"Implemented")+COUNTIF(F10:M10,"Partial")+COUNTIF(F10:M10,"Not Implemented"))=0,"??",IF(COUNTIF(F10:M10,"Implemented")=(COUNTIF(F10:M10,"Implemented")+COUNTIF(F10:M10,"Partial")+COUNTIF(F10:M10,"Not Implemented")),"Implemented",IF(COUNTIF(F10:M10,"Not Implemented")=(COUNTIF(F10:M10,"Implemented")+COUNTIF(F10:M10,"Partial")+COUNTIF(F10:M10,"Not Implemented")),"Not Implemented","Partial"))))) -> Partial | O10: =IF(COUNTA(F10:M10)=0,"",(COUNTIF(F10:M10,"Implemented")+COUNTIF(F10:M10,"Partial")+COUNTIF(F10:M10,"Not Implemented"))) -> 3 | P10: =IF(COUNTA(F10:M10)=0,"",COUNTIF(F10:M10,"??")) -> 0 | Q10: =IF(COUNTA(F10:M10)=0,"",COUNTIF(F10:M10,"Partial")+COUNTIF(F10:M10,"Not Implemented")) -> 2 | R10: AA-01: Unique, strong password stored in password manager; not reused elsewhere; recovery email/phone current AA-03: MFA method available and enabled at the bank AA-05: Active sessions, connected third-party apps, and shared access reviewed | S10: AA-01: Unique 16+ char password in password manager; recovery contacts verified AA-03: Strongest MFA the bank supports; SMS only if no alternative AA-05: Only current sessions / needed apps; reviewed quarterly | T10: A unique password is used and stored in a password manager. Recovery email and phone information are current. MFA is enabled using SMS. | U10: SMS-based MFA provides additional protection, but it is more exposed to SIM-swap or phone-number takeover risks than stronger authentication methods. | V10: User confirmed a unique password, password manager use, current recovery information, and SMS-based MFA. | W10: Keep the unique password and password manager. If the bank supports a stronger MFA option, migrate from SMS. | X10: F3 | Y10: PR-004, PR-015 | Z10: [PR-004] Password / recovery elements of AA-01 appear fully met; the gap described (SMS-based MFA) belongs to AA-03. Suggested: AA-01 Implemented, AA-03 Partial.
A11: AST-007 | B11: =IF(A11="","",IFERROR(INDEX('Asset Register'!$B:$B,MATCH(A11,'Asset Register'!$A:$A,0)),"")) -> A-F02 | C11: =IF(A11="","",IFERROR(INDEX('Asset Register'!$E:$E,MATCH(A11,'Asset Register'!$A:$A,0)),"")) -> International transfer service | D11: =IF(A11="","",IFERROR(INDEX('Asset Register'!$D:$D,MATCH(A11,'Asset Register'!$A:$A,0)),"")) -> Financial | E11: =IF(A11="","",IFERROR(INDEX('Asset Register'!$J:$J,MATCH(A11,'Asset Register'!$A:$A,0)),"")) -> Critical | F11: Implemented | G11: Not Implemented | H11: Partial | I11: N/A | J11: N/A | K11: N/A | L11: N/A | M11: N/A | N11: =IF(COUNTA(F11:M11)=0,"",IF((COUNTIF(F11:M11,"Implemented")+COUNTIF(F11:M11,"Partial")+COUNTIF(F11:M11,"Not Implemented"))+COUNTIF(F11:M11,"??")=0,"N/A",IF((COUNTIF(F11:M11,"Implemented")+COUNTIF(F11:M11,"Partial")+COUNTIF(F11:M11,"Not Implemented"))=0,"??",IF(COUNTIF(F11:M11,"Implemented")=(COUNTIF(F11:M11,"Implemented")+COUNTIF(F11:M11,"Partial")+COUNTIF(F11:M11,"Not Implemented")),"Implemented",IF(COUNTIF(F11:M11,"Not Implemented")=(COUNTIF(F11:M11,"Implemented")+COUNTIF(F11:M11,"Partial")+COUNTIF(F11:M11,"Not Implemented")),"Not Implemented","Partial"))))) -> Partial | O11: =IF(COUNTA(F11:M11)=0,"",(COUNTIF(F11:M11,"Implemented")+COUNTIF(F11:M11,"Partial")+COUNTIF(F11:M11,"Not Implemented"))) -> 3 | P11: =IF(COUNTA(F11:M11)=0,"",COUNTIF(F11:M11,"??")) -> 0 | Q11: =IF(COUNTA(F11:M11)=0,"",COUNTIF(F11:M11,"Partial")+COUNTIF(F11:M11,"Not Implemented")) -> 2 | R11: AA-01: Unique, strong password stored in password manager; not reused elsewhere; recovery email/phone current AA-03: MFA method enabled AA-05: Active sessions, connected third-party apps, and shared access reviewed | S11: AA-01: Unique 16+ char password in password manager; recovery contacts verified AA-03: Authenticator app or passkey AA-05: Only current sessions / needed apps; reviewed quarterly | T11: A unique password is used and stored in a password manager. Recovery email and phone information are current. MFA is not enabled, and the available MFA method has not been verified. | U11: Without MFA, a stolen or exposed password could be enough to access the account and potentially initiate unauthorized transfers. | V11: User confirmed a unique password, password manager use, current recovery information, and no MFA. | W11: Enable MFA using the strongest method supported by the service and verify the available authentication options. | X11: F3 | Y11: PR-005, PR-016 | Z11: [PR-005] Password / recovery elements of AA-01 appear fully met; the gap described (no MFA) belongs to AA-03. Suggested: AA-01 Implemented, AA-03 Not Implemented.
A12: AST-008 | B12: =IF(A12="","",IFERROR(INDEX('Asset Register'!$B:$B,MATCH(A12,'Asset Register'!$A:$A,0)),"")) -> A-F03 | C12: =IF(A12="","",IFERROR(INDEX('Asset Register'!$E:$E,MATCH(A12,'Asset Register'!$A:$A,0)),"")) -> Credit card portal (x1) | D12: =IF(A12="","",IFERROR(INDEX('Asset Register'!$D:$D,MATCH(A12,'Asset Register'!$A:$A,0)),"")) -> Financial | E12: =IF(A12="","",IFERROR(INDEX('Asset Register'!$J:$J,MATCH(A12,'Asset Register'!$A:$A,0)),"")) -> Critical | F12: Implemented | G12: Implemented | H12: Partial | I12: N/A | J12: N/A | K12: N/A | L12: N/A | M12: N/A | N12: =IF(COUNTA(F12:M12)=0,"",IF((COUNTIF(F12:M12,"Implemented")+COUNTIF(F12:M12,"Partial")+COUNTIF(F12:M12,"Not Implemented"))+COUNTIF(F12:M12,"??")=0,"N/A",IF((COUNTIF(F12:M12,"Implemented")+COUNTIF(F12:M12,"Partial")+COUNTIF(F12:M12,"Not Implemented"))=0,"??",IF(COUNTIF(F12:M12,"Implemented")=(COUNTIF(F12:M12,"Implemented")+COUNTIF(F12:M12,"Partial")+COUNTIF(F12:M12,"Not Implemented")),"Implemented",IF(COUNTIF(F12:M12,"Not Implemented")=(COUNTIF(F12:M12,"Implemented")+COUNTIF(F12:M12,"Partial")+COUNTIF(F12:M12,"Not Implemented")),"Not Implemented","Partial"))))) -> Partial | O12: =IF(COUNTA(F12:M12)=0,"",(COUNTIF(F12:M12,"Implemented")+COUNTIF(F12:M12,"Partial")+COUNTIF(F12:M12,"Not Implemented"))) -> 3 | P12: =IF(COUNTA(F12:M12)=0,"",COUNTIF(F12:M12,"??")) -> 0 | Q12: =IF(COUNTA(F12:M12)=0,"",COUNTIF(F12:M12,"Partial")+COUNTIF(F12:M12,"Not Implemented")) -> 1 | R12: AA-01: Unique, strong password stored in password manager; not reused elsewhere; recovery email/phone current AA-03: MFA method enabled AA-05: Active sessions, connected third-party apps, and shared access reviewed | S12: AA-01: Unique 16+ char password in password manager; recovery contacts verified AA-03: Strongest MFA the issuer supports AA-05: Only current sessions / needed apps; reviewed quarterly | T12: A unique password is used and stored in a password manager. Recovery email and phone information are current. MFA is enabled. Active sessions, connected third-party applications, and shared access have not yet been reviewed. | U12: Unreviewed sessions or connected applications may retain unnecessary or unauthorized access to the credit card account. | V12: User confirmed a unique password, password manager use, current recovery information, and MFA enabled. Access review remains unverified. | W12: Review active sessions, connected applications, and shared access. Remove anything that is no longer needed and periodically repeat the review. | X12: F3 | Y12: PR-006, PR-017
A13: AST-009 | B13: =IF(A13="","",IFERROR(INDEX('Asset Register'!$B:$B,MATCH(A13,'Asset Register'!$A:$A,0)),"")) -> A-F04 | C13: =IF(A13="","",IFERROR(INDEX('Asset Register'!$E:$E,MATCH(A13,'Asset Register'!$A:$A,0)),"")) -> Debit card portals (x4) | D13: =IF(A13="","",IFERROR(INDEX('Asset Register'!$D:$D,MATCH(A13,'Asset Register'!$A:$A,0)),"")) -> Financial | E13: =IF(A13="","",IFERROR(INDEX('Asset Register'!$J:$J,MATCH(A13,'Asset Register'!$A:$A,0)),"")) -> High | F13: Implemented | G13: Implemented | H13: Partial | I13: N/A | J13: N/A | K13: N/A | L13: N/A | M13: N/A | N13: =IF(COUNTA(F13:M13)=0,"",IF((COUNTIF(F13:M13,"Implemented")+COUNTIF(F13:M13,"Partial")+COUNTIF(F13:M13,"Not Implemented"))+COUNTIF(F13:M13,"??")=0,"N/A",IF((COUNTIF(F13:M13,"Implemented")+COUNTIF(F13:M13,"Partial")+COUNTIF(F13:M13,"Not Implemented"))=0,"??",IF(COUNTIF(F13:M13,"Implemented")=(COUNTIF(F13:M13,"Implemented")+COUNTIF(F13:M13,"Partial")+COUNTIF(F13:M13,"Not Implemented")),"Implemented",IF(COUNTIF(F13:M13,"Not Implemented")=(COUNTIF(F13:M13,"Implemented")+COUNTIF(F13:M13,"Partial")+COUNTIF(F13:M13,"Not Implemented")),"Not Implemented","Partial"))))) -> Partial | O13: =IF(COUNTA(F13:M13)=0,"",(COUNTIF(F13:M13,"Implemented")+COUNTIF(F13:M13,"Partial")+COUNTIF(F13:M13,"Not Implemented"))) -> 3 | P13: =IF(COUNTA(F13:M13)=0,"",COUNTIF(F13:M13,"??")) -> 0 | Q13: =IF(COUNTA(F13:M13)=0,"",COUNTIF(F13:M13,"Partial")+COUNTIF(F13:M13,"Not Implemented")) -> 1 | R13: AA-01: Unique, strong password stored in password manager; not reused elsewhere; recovery email/phone current AA-03: MFA enabled and which method (passkey / authenticator app / SMS) AA-05: Active sessions, connected third-party apps, and shared access reviewed | S13: AA-01: Unique 16+ char password in password manager; recovery contacts verified AA-03: Strongest MFA the service supports; SMS only if no alternative AA-05: Only current sessions / needed apps; reviewed quarterly | T13: A unique password is used and stored in a password manager. Recovery email and phone information are current. MFA is enabled. Active sessions, connected third-party applications, and shared access have not yet been reviewed. | U13: Unreviewed sessions or connected applications may retain unnecessary or unauthorized access to the credit card account. | V13: User confirmed a unique password, password manager use, current recovery information, and MFA enabled. Access review remains unverified. | W13: Review active sessions, connected applications, and shared access. Remove anything that is no longer needed and periodically repeat the review.
A14: AST-010 | B14: =IF(A14="","",IFERROR(INDEX('Asset Register'!$B:$B,MATCH(A14,'Asset Register'!$A:$A,0)),"")) -> A-F05 | C14: =IF(A14="","",IFERROR(INDEX('Asset Register'!$E:$E,MATCH(A14,'Asset Register'!$A:$A,0)),"")) -> Apple Pay | D14: =IF(A14="","",IFERROR(INDEX('Asset Register'!$D:$D,MATCH(A14,'Asset Register'!$A:$A,0)),"")) -> Financial | E14: =IF(A14="","",IFERROR(INDEX('Asset Register'!$J:$J,MATCH(A14,'Asset Register'!$A:$A,0)),"")) -> Critical | F14: N/A | G14: Implemented | H14: Implemented | I14: N/A | J14: N/A | K14: N/A | L14: N/A | M14: N/A | N14: =IF(COUNTA(F14:M14)=0,"",IF((COUNTIF(F14:M14,"Implemented")+COUNTIF(F14:M14,"Partial")+COUNTIF(F14:M14,"Not Implemented"))+COUNTIF(F14:M14,"??")=0,"N/A",IF((COUNTIF(F14:M14,"Implemented")+COUNTIF(F14:M14,"Partial")+COUNTIF(F14:M14,"Not Implemented"))=0,"??",IF(COUNTIF(F14:M14,"Implemented")=(COUNTIF(F14:M14,"Implemented")+COUNTIF(F14:M14,"Partial")+COUNTIF(F14:M14,"Not Implemented")),"Implemented",IF(COUNTIF(F14:M14,"Not Implemented")=(COUNTIF(F14:M14,"Implemented")+COUNTIF(F14:M14,"Partial")+COUNTIF(F14:M14,"Not Implemented")),"Not Implemented","Partial"))))) -> Implemented | O14: =IF(COUNTA(F14:M14)=0,"",(COUNTIF(F14:M14,"Implemented")+COUNTIF(F14:M14,"Partial")+COUNTIF(F14:M14,"Not Implemented"))) -> 2 | P14: =IF(COUNTA(F14:M14)=0,"",COUNTIF(F14:M14,"??")) -> 0 | Q14: =IF(COUNTA(F14:M14)=0,"",COUNTIF(F14:M14,"Partial")+COUNTIF(F14:M14,"Not Implemented")) -> 0 | R14: AA-03: Per-transaction authentication (Face ID / passcode) AA-05: Devices holding the cards reviewed; unused cards removed | S14: AA-03: Every payment requires Face ID or passcode AA-05: Cards only on devices in use; unused cards removed | T14: Apple Pay requires biometric authentication or a device passcode for each payment. Registered cards and devices have been reviewed, and no unnecessary cards or old devices were identified. | U14: Current authentication and access controls reduce the risk of unauthorized payments. Remaining risk would mainly arise if an authorized device were compromised or device access controls were weakened. | V14: User confirmed that every Apple Pay payment requires Face ID, Touch ID, or a passcode, and that registered cards and devices have been reviewed with no unnecessary entries found. | W14: Keep device authentication enabled and periodically review registered cards and devices. Remove any card or device that is no longer in use.
A15: AST-011 | B15: =IF(A15="","",IFERROR(INDEX('Asset Register'!$B:$B,MATCH(A15,'Asset Register'!$A:$A,0)),"")) -> A-F06 | C15: =IF(A15="","",IFERROR(INDEX('Asset Register'!$E:$E,MATCH(A15,'Asset Register'!$A:$A,0)),"")) -> P2P payment app | D15: =IF(A15="","",IFERROR(INDEX('Asset Register'!$D:$D,MATCH(A15,'Asset Register'!$A:$A,0)),"")) -> Financial | E15: =IF(A15="","",IFERROR(INDEX('Asset Register'!$J:$J,MATCH(A15,'Asset Register'!$A:$A,0)),"")) -> High | F15: Partial | G15: Implemented | H15: Partial | I15: N/A | J15: N/A | K15: N/A | L15: N/A | M15: N/A | N15: =IF(COUNTA(F15:M15)=0,"",IF((COUNTIF(F15:M15,"Implemented")+COUNTIF(F15:M15,"Partial")+COUNTIF(F15:M15,"Not Implemented"))+COUNTIF(F15:M15,"??")=0,"N/A",IF((COUNTIF(F15:M15,"Implemented")+COUNTIF(F15:M15,"Partial")+COUNTIF(F15:M15,"Not Implemented"))=0,"??",IF(COUNTIF(F15:M15,"Implemented")=(COUNTIF(F15:M15,"Implemented")+COUNTIF(F15:M15,"Partial")+COUNTIF(F15:M15,"Not Implemented")),"Implemented",IF(COUNTIF(F15:M15,"Not Implemented")=(COUNTIF(F15:M15,"Implemented")+COUNTIF(F15:M15,"Partial")+COUNTIF(F15:M15,"Not Implemented")),"Not Implemented","Partial"))))) -> Partial | O15: =IF(COUNTA(F15:M15)=0,"",(COUNTIF(F15:M15,"Implemented")+COUNTIF(F15:M15,"Partial")+COUNTIF(F15:M15,"Not Implemented"))) -> 3 | P15: =IF(COUNTA(F15:M15)=0,"",COUNTIF(F15:M15,"??")) -> 0 | Q15: =IF(COUNTA(F15:M15)=0,"",COUNTIF(F15:M15,"Partial")+COUNTIF(F15:M15,"Not Implemented")) -> 2 | R15: AA-01: Unique, strong password stored in password manager; not reused elsewhere; recovery email/phone current AA-03: MFA enabled and which method (passkey / authenticator app / SMS) AA-05: Active sessions, connected third-party apps, and shared access reviewed | S15: AA-01: Unique 16+ char password in password manager; recovery contacts verified AA-03: Strongest MFA the service supports; SMS only if no alternative AA-05: Only current sessions / needed apps; reviewed quarterly | T15: The account password is managed with a password manager. Passkey authentication is enabled. Active sessions, connected applications, and shared access have not yet been reviewed. Password reuse and recovery contact status have not yet been verified. | U15: Unreviewed sessions or connected applications could retain unnecessary access. If recovery information is outdated or the password is reused elsewhere, account recovery or credential compromise risk may increase. | V15: User confirmed that the password is managed with a password manager and passkey authentication is enabled. Active sessions, connected applications, and shared access have not yet been reviewed. Password reuse and recovery contact status remain unverified. | W15: Verify that the password is unique, confirm recovery email and phone information, and review active sessions and connected applications.
A16: AST-012 | B16: =IF(A16="","",IFERROR(INDEX('Asset Register'!$B:$B,MATCH(A16,'Asset Register'!$A:$A,0)),"")) -> A-F07 | C16: =IF(A16="","",IFERROR(INDEX('Asset Register'!$E:$E,MATCH(A16,'Asset Register'!$A:$A,0)),"")) -> Bank-integrated transfer service | D16: =IF(A16="","",IFERROR(INDEX('Asset Register'!$D:$D,MATCH(A16,'Asset Register'!$A:$A,0)),"")) -> Financial | E16: =IF(A16="","",IFERROR(INDEX('Asset Register'!$J:$J,MATCH(A16,'Asset Register'!$A:$A,0)),"")) -> High | F16: Partial | G16: Implemented | H16: Partial | I16: N/A | J16: N/A | K16: N/A | L16: N/A | M16: N/A | N16: =IF(COUNTA(F16:M16)=0,"",IF((COUNTIF(F16:M16,"Implemented")+COUNTIF(F16:M16,"Partial")+COUNTIF(F16:M16,"Not Implemented"))+COUNTIF(F16:M16,"??")=0,"N/A",IF((COUNTIF(F16:M16,"Implemented")+COUNTIF(F16:M16,"Partial")+COUNTIF(F16:M16,"Not Implemented"))=0,"??",IF(COUNTIF(F16:M16,"Implemented")=(COUNTIF(F16:M16,"Implemented")+COUNTIF(F16:M16,"Partial")+COUNTIF(F16:M16,"Not Implemented")),"Implemented",IF(COUNTIF(F16:M16,"Not Implemented")=(COUNTIF(F16:M16,"Implemented")+COUNTIF(F16:M16,"Partial")+COUNTIF(F16:M16,"Not Implemented")),"Not Implemented","Partial"))))) -> Partial | O16: =IF(COUNTA(F16:M16)=0,"",(COUNTIF(F16:M16,"Implemented")+COUNTIF(F16:M16,"Partial")+COUNTIF(F16:M16,"Not Implemented"))) -> 3 | P16: =IF(COUNTA(F16:M16)=0,"",COUNTIF(F16:M16,"??")) -> 0 | Q16: =IF(COUNTA(F16:M16)=0,"",COUNTIF(F16:M16,"Partial")+COUNTIF(F16:M16,"Not Implemented")) -> 2 | R16: AA-01: Unique, strong password stored in password manager; not reused elsewhere; recovery email/phone current AA-03: MFA enabled and which method (passkey / authenticator app / SMS) AA-05: Active sessions, connected third-party apps, and shared access reviewed | S16: AA-01: Unique 16+ char password in password manager; recovery contacts verified AA-03: Strongest MFA the service supports; SMS only if no alternative AA-05: Only current sessions / needed apps; reviewed quarterly | T16: The account password is managed with a password manager, and passkey authentication is enabled. Active sessions, connected third-party applications, and shared access have not yet been reviewed. | U16: Unreviewed sessions or connected applications could retain unnecessary access. If the password is reused or recovery information is outdated, account compromise or recovery risk may increase. | V16: User confirmed password manager use and passkey authentication. Active sessions, connected applications, shared access, password reuse, and recovery contact status remain unverified. | W16: Verify that the password is unique, confirm recovery email and phone information, and review active sessions and connected applications.
A17: AST-013 | B17: =IF(A17="","",IFERROR(INDEX('Asset Register'!$B:$B,MATCH(A17,'Asset Register'!$A:$A,0)),"")) -> A-I01 | C17: =IF(A17="","",IFERROR(INDEX('Asset Register'!$E:$E,MATCH(A17,'Asset Register'!$A:$A,0)),"")) -> Gmail (primary) | D17: =IF(A17="","",IFERROR(INDEX('Asset Register'!$D:$D,MATCH(A17,'Asset Register'!$A:$A,0)),"")) -> Identity & Email | E17: =IF(A17="","",IFERROR(INDEX('Asset Register'!$J:$J,MATCH(A17,'Asset Register'!$A:$A,0)),"")) -> Critical | F17: Partial | G17: Implemented | H17: Implemented | I17: N/A | J17: N/A | K17: N/A | L17: N/A | M17: N/A | N17: =IF(COUNTA(F17:M17)=0,"",IF((COUNTIF(F17:M17,"Implemented")+COUNTIF(F17:M17,"Partial")+COUNTIF(F17:M17,"Not Implemented"))+COUNTIF(F17:M17,"??")=0,"N/A",IF((COUNTIF(F17:M17,"Implemented")+COUNTIF(F17:M17,"Partial")+COUNTIF(F17:M17,"Not Implemented"))=0,"??",IF(COUNTIF(F17:M17,"Implemented")=(COUNTIF(F17:M17,"Implemented")+COUNTIF(F17:M17,"Partial")+COUNTIF(F17:M17,"Not Implemented")),"Implemented",IF(COUNTIF(F17:M17,"Not Implemented")=(COUNTIF(F17:M17,"Implemented")+COUNTIF(F17:M17,"Partial")+COUNTIF(F17:M17,"Not Implemented")),"Not Implemented","Partial"))))) -> Partial | O17: =IF(COUNTA(F17:M17)=0,"",(COUNTIF(F17:M17,"Implemented")+COUNTIF(F17:M17,"Partial")+COUNTIF(F17:M17,"Not Implemented"))) -> 3 | P17: =IF(COUNTA(F17:M17)=0,"",COUNTIF(F17:M17,"??")) -> 0 | Q17: =IF(COUNTA(F17:M17)=0,"",COUNTIF(F17:M17,"Partial")+COUNTIF(F17:M17,"Not Implemented")) -> 1 | R17: AA-01: Unique, strong password stored in password manager; not reused elsewhere; recovery email/phone current (password-reset hub for most services) AA-03: MFA enabled and which method (passkey / authenticator app / SMS) AA-05: Active sessions, connected third-party apps, and shared access reviewed | S17: AA-01: Unique 16+ char password in password manager; recovery contacts verified AA-03: Strongest MFA the service supports; SMS only if no alternative AA-05: Only current sessions / needed apps; reviewed quarterly | T17: Gmail uses the same password as the Google Account. The password is managed through the Google Account credential | U17: Reuse of the same credential across related services may increase account compromise risk if the credential is exposed. | V17: User confirmed Gmail uses the same password as the Google Account. | W17: Keep the Google Account credential unique from unrelated services and continue managing it securely with a password manager. | Y17: PR-003 | Z17: [PR-003] Gmail uses the Google Account credential (AST-018), where password reuse was recorded, but Remediation here says 'keep ... unique'. Consider aligning the text with AST-018, or marking AA-01 / AA-03 as N/A with 'covered by AST-018'.
A18: AST-014 | B18: =IF(A18="","",IFERROR(INDEX('Asset Register'!$B:$B,MATCH(A18,'Asset Register'!$A:$A,0)),"")) -> A-I02 | C18: =IF(A18="","",IFERROR(INDEX('Asset Register'!$E:$E,MATCH(A18,'Asset Register'!$A:$A,0)),"")) -> Gmail (secondary) | D18: =IF(A18="","",IFERROR(INDEX('Asset Register'!$D:$D,MATCH(A18,'Asset Register'!$A:$A,0)),"")) -> Identity & Email | E18: =IF(A18="","",IFERROR(INDEX('Asset Register'!$J:$J,MATCH(A18,'Asset Register'!$A:$A,0)),"")) -> High | F18: Implemented | G18: Implemented | H18: Implemented | I18: N/A | J18: N/A | K18: N/A | L18: N/A | M18: N/A | N18: =IF(COUNTA(F18:M18)=0,"",IF((COUNTIF(F18:M18,"Implemented")+COUNTIF(F18:M18,"Partial")+COUNTIF(F18:M18,"Not Implemented"))+COUNTIF(F18:M18,"??")=0,"N/A",IF((COUNTIF(F18:M18,"Implemented")+COUNTIF(F18:M18,"Partial")+COUNTIF(F18:M18,"Not Implemented"))=0,"??",IF(COUNTIF(F18:M18,"Implemented")=(COUNTIF(F18:M18,"Implemented")+COUNTIF(F18:M18,"Partial")+COUNTIF(F18:M18,"Not Implemented")),"Implemented",IF(COUNTIF(F18:M18,"Not Implemented")=(COUNTIF(F18:M18,"Implemented")+COUNTIF(F18:M18,"Partial")+COUNTIF(F18:M18,"Not Implemented")),"Not Implemented","Partial"))))) -> Implemented | O18: =IF(COUNTA(F18:M18)=0,"",(COUNTIF(F18:M18,"Implemented")+COUNTIF(F18:M18,"Partial")+COUNTIF(F18:M18,"Not Implemented"))) -> 3 | P18: =IF(COUNTA(F18:M18)=0,"",COUNTIF(F18:M18,"??")) -> 0 | Q18: =IF(COUNTA(F18:M18)=0,"",COUNTIF(F18:M18,"Partial")+COUNTIF(F18:M18,"Not Implemented")) -> 0 | R18: AA-01: Account purpose defined, or dormant account retired AA-03: MFA enabled and which method (passkey / authenticator app / SMS) AA-05: Active sessions, connected third-party apps, and shared access reviewed | S18: AA-01: Purpose documented or account deleted AA-03: Strongest MFA the service supports; SMS only if no alternative AA-05: Only current sessions / needed apps; reviewed quarterly | T18: Gmail uses the same password as the Google Account. The password is managed through the Google Account credential | U18: Reuse of the same credential across related services may increase account compromise risk if the credential is exposed. | V18: User confirmed Gmail uses the same password as the Google Account. | W18: Keep the Google Account credential unique from unrelated services and continue managing it securely with a password manager. | Y18: PR-011
A19: AST-015 | B19: =IF(A19="","",IFERROR(INDEX('Asset Register'!$B:$B,MATCH(A19,'Asset Register'!$A:$A,0)),"")) -> A-I03 | C19: =IF(A19="","",IFERROR(INDEX('Asset Register'!$E:$E,MATCH(A19,'Asset Register'!$A:$A,0)),"")) -> College email | D19: =IF(A19="","",IFERROR(INDEX('Asset Register'!$D:$D,MATCH(A19,'Asset Register'!$A:$A,0)),"")) -> Identity & Email | E19: =IF(A19="","",IFERROR(INDEX('Asset Register'!$J:$J,MATCH(A19,'Asset Register'!$A:$A,0)),"")) -> High | F19: Partial | G19: Implemented | H19: Partial | I19: N/A | J19: N/A | K19: N/A | L19: N/A | M19: N/A | N19: =IF(COUNTA(F19:M19)=0,"",IF((COUNTIF(F19:M19,"Implemented")+COUNTIF(F19:M19,"Partial")+COUNTIF(F19:M19,"Not Implemented"))+COUNTIF(F19:M19,"??")=0,"N/A",IF((COUNTIF(F19:M19,"Implemented")+COUNTIF(F19:M19,"Partial")+COUNTIF(F19:M19,"Not Implemented"))=0,"??",IF(COUNTIF(F19:M19,"Implemented")=(COUNTIF(F19:M19,"Implemented")+COUNTIF(F19:M19,"Partial")+COUNTIF(F19:M19,"Not Implemented")),"Implemented",IF(COUNTIF(F19:M19,"Not Implemented")=(COUNTIF(F19:M19,"Implemented")+COUNTIF(F19:M19,"Partial")+COUNTIF(F19:M19,"Not Implemented")),"Not Implemented","Partial"))))) -> Partial | O19: =IF(COUNTA(F19:M19)=0,"",(COUNTIF(F19:M19,"Implemented")+COUNTIF(F19:M19,"Partial")+COUNTIF(F19:M19,"Not Implemented"))) -> 3 | P19: =IF(COUNTA(F19:M19)=0,"",COUNTIF(F19:M19,"??")) -> 0 | Q19: =IF(COUNTA(F19:M19)=0,"",COUNTIF(F19:M19,"Partial")+COUNTIF(F19:M19,"Not Implemented")) -> 2 | R19: AA-01: Unique, strong password stored in password manager; not reused elsewhere; recovery email/phone current AA-03: MFA enabled and which method (passkey / authenticator app / SMS) AA-05: Active sessions, connected third-party apps, and shared access reviewed | S19: AA-01: Unique 16+ char password in password manager; recovery contacts verified AA-03: Strongest MFA the service supports; SMS only if no alternative AA-05: Only current sessions / needed apps; reviewed quarterly | T19: The college email uses a unique password, and MFA is enabled with an authenticator app. Active sessions, connected applications, and shared access have not yet been reviewed. Password manager use and recovery contact status remain unverified. | U19: Unreviewed sessions or connected applications may retain unnecessary access. If recovery information is outdated, account recovery could be more difficult. | V19: User confirmed that the password is not reused and authenticator-app MFA is enabled. Active sessions, connected applications, shared access, password manager use, and recovery contact status remain unverified. | W19: Verify recovery email and phone information, confirm secure password storage, and review active sessions and connected applications periodically.
A20: AST-016 | B20: =IF(A20="","",IFERROR(INDEX('Asset Register'!$B:$B,MATCH(A20,'Asset Register'!$A:$A,0)),"")) -> A-I04 | C20: =IF(A20="","",IFERROR(INDEX('Asset Register'!$E:$E,MATCH(A20,'Asset Register'!$A:$A,0)),"")) -> Outlook account | D20: =IF(A20="","",IFERROR(INDEX('Asset Register'!$D:$D,MATCH(A20,'Asset Register'!$A:$A,0)),"")) -> Identity & Email | E20: =IF(A20="","",IFERROR(INDEX('Asset Register'!$J:$J,MATCH(A20,'Asset Register'!$A:$A,0)),"")) -> Medium | F20: Partial | G20: Implemented | H20: Partial | I20: N/A | J20: N/A | K20: N/A | L20: N/A | M20: N/A | N20: =IF(COUNTA(F20:M20)=0,"",IF((COUNTIF(F20:M20,"Implemented")+COUNTIF(F20:M20,"Partial")+COUNTIF(F20:M20,"Not Implemented"))+COUNTIF(F20:M20,"??")=0,"N/A",IF((COUNTIF(F20:M20,"Implemented")+COUNTIF(F20:M20,"Partial")+COUNTIF(F20:M20,"Not Implemented"))=0,"??",IF(COUNTIF(F20:M20,"Implemented")=(COUNTIF(F20:M20,"Implemented")+COUNTIF(F20:M20,"Partial")+COUNTIF(F20:M20,"Not Implemented")),"Implemented",IF(COUNTIF(F20:M20,"Not Implemented")=(COUNTIF(F20:M20,"Implemented")+COUNTIF(F20:M20,"Partial")+COUNTIF(F20:M20,"Not Implemented")),"Not Implemented","Partial"))))) -> Partial | O20: =IF(COUNTA(F20:M20)=0,"",(COUNTIF(F20:M20,"Implemented")+COUNTIF(F20:M20,"Partial")+COUNTIF(F20:M20,"Not Implemented"))) -> 3 | P20: =IF(COUNTA(F20:M20)=0,"",COUNTIF(F20:M20,"??")) -> 0 | Q20: =IF(COUNTA(F20:M20)=0,"",COUNTIF(F20:M20,"Partial")+COUNTIF(F20:M20,"Not Implemented")) -> 2 | R20: AA-01: Unique, strong password stored in password manager; not reused elsewhere; recovery email/phone current AA-03: MFA enabled and which method (passkey / authenticator app / SMS) AA-05: Active sessions, connected third-party apps, and shared access reviewed | S20: AA-01: Unique 16+ char password in password manager; recovery contacts verified AA-03: Strongest MFA the service supports; SMS only if no alternative AA-05: Only current sessions / needed apps; reviewed quarterly | T20: The Outlook account credential is managed with a password manager, and passkey authentication is enabled. Active sessions, connected applications, and shared access have not yet been reviewed. Password reuse and recovery contact status remain unverified. | U20: Unreviewed sessions or applications could retain unnecessary access. Unverified recovery information or password reuse could increase account-compromise or recovery risk. | V20: User confirmed password manager use and passkey authentication. Active sessions, connected applications, shared access, password reuse, and recovery contact status remain unverified. | W20: Verify that the password is unique, confirm recovery email and phone information, and review active sessions and connected applications.
A21: AST-017 | B21: =IF(A21="","",IFERROR(INDEX('Asset Register'!$B:$B,MATCH(A21,'Asset Register'!$A:$A,0)),"")) -> A-I05 | C21: =IF(A21="","",IFERROR(INDEX('Asset Register'!$E:$E,MATCH(A21,'Asset Register'!$A:$A,0)),"")) -> Apple ID | D21: =IF(A21="","",IFERROR(INDEX('Asset Register'!$D:$D,MATCH(A21,'Asset Register'!$A:$A,0)),"")) -> Identity & Email | E21: =IF(A21="","",IFERROR(INDEX('Asset Register'!$J:$J,MATCH(A21,'Asset Register'!$A:$A,0)),"")) -> Critical | F21: Implemented | G21: Implemented | H21: Partial | I21: N/A | J21: N/A | K21: N/A | L21: N/A | M21: N/A | N21: =IF(COUNTA(F21:M21)=0,"",IF((COUNTIF(F21:M21,"Implemented")+COUNTIF(F21:M21,"Partial")+COUNTIF(F21:M21,"Not Implemented"))+COUNTIF(F21:M21,"??")=0,"N/A",IF((COUNTIF(F21:M21,"Implemented")+COUNTIF(F21:M21,"Partial")+COUNTIF(F21:M21,"Not Implemented"))=0,"??",IF(COUNTIF(F21:M21,"Implemented")=(COUNTIF(F21:M21,"Implemented")+COUNTIF(F21:M21,"Partial")+COUNTIF(F21:M21,"Not Implemented")),"Implemented",IF(COUNTIF(F21:M21,"Not Implemented")=(COUNTIF(F21:M21,"Implemented")+COUNTIF(F21:M21,"Partial")+COUNTIF(F21:M21,"Not Implemented")),"Not Implemented","Partial"))))) -> Partial | O21: =IF(COUNTA(F21:M21)=0,"",(COUNTIF(F21:M21,"Implemented")+COUNTIF(F21:M21,"Partial")+COUNTIF(F21:M21,"Not Implemented"))) -> 3 | P21: =IF(COUNTA(F21:M21)=0,"",COUNTIF(F21:M21,"??")) -> 0 | Q21: =IF(COUNTA(F21:M21)=0,"",COUNTIF(F21:M21,"Partial")+COUNTIF(F21:M21,"Not Implemented")) -> 1 | R21: AA-01: Unique, strong password stored in password manager; not reused elsewhere; recovery email/phone current; recovery key / recovery contact configured AA-03: Two-factor authentication method and trusted phone numbers AA-05: Trusted devices list and Family Sharing / shared access reviewed | S21: AA-01: Unique 16+ char password in password manager; recovery contacts verified; Recovery Key or Recovery Contact set AA-03: Phishing-resistant MFA (passkey / security key) or authenticator app; SMS removed as a factor; security keys registered for Apple ID AA-05: Only current devices listed; reviewed quarterly | T21: The Apple ID password was previously reused across multiple accounts and memorized. The password has since been changed to a new password. The recovery phone number has not been verified. No Recovery Contact or Recovery Key is configured. | U21: Weak recovery configuration may delay or complicate account recovery if access is lost. | V21: Password reuse was identified during the initial assessment. The password was later changed. Recovery phone number remains unverified, and no Recovery Contact or Recovery Key is configured | W21: Verify the trusted recovery phone number and configure an appropriate recovery method. | X21: F2 | Y21: PR-001, PR-013, PR-022 | Z21: [PR-001] AA-01: Current State does not say whether the new password is stored in the password manager or meets the 16+ char target; add that to confirm AA-01. AA-05: Detect sheet (old DE-041) records that the device list was reviewed and all devices were recognized — usable evidence for AA-05.
A22: AST-018 | B22: =IF(A22="","",IFERROR(INDEX('Asset Register'!$B:$B,MATCH(A22,'Asset Register'!$A:$A,0)),"")) -> A-I06 | C22: =IF(A22="","",IFERROR(INDEX('Asset Register'!$E:$E,MATCH(A22,'Asset Register'!$A:$A,0)),"")) -> Google Account | D22: =IF(A22="","",IFERROR(INDEX('Asset Register'!$D:$D,MATCH(A22,'Asset Register'!$A:$A,0)),"")) -> Identity & Email | E22: =IF(A22="","",IFERROR(INDEX('Asset Register'!$J:$J,MATCH(A22,'Asset Register'!$A:$A,0)),"")) -> Critical | F22: Partial | G22: Implemented | H22: Partial | I22: N/A | J22: N/A | K22: N/A | L22: N/A | M22: N/A | N22: =IF(COUNTA(F22:M22)=0,"",IF((COUNTIF(F22:M22,"Implemented")+COUNTIF(F22:M22,"Partial")+COUNTIF(F22:M22,"Not Implemented"))+COUNTIF(F22:M22,"??")=0,"N/A",IF((COUNTIF(F22:M22,"Implemented")+COUNTIF(F22:M22,"Partial")+COUNTIF(F22:M22,"Not Implemented"))=0,"??",IF(COUNTIF(F22:M22,"Implemented")=(COUNTIF(F22:M22,"Implemented")+COUNTIF(F22:M22,"Partial")+COUNTIF(F22:M22,"Not Implemented")),"Implemented",IF(COUNTIF(F22:M22,"Not Implemented")=(COUNTIF(F22:M22,"Implemented")+COUNTIF(F22:M22,"Partial")+COUNTIF(F22:M22,"Not Implemented")),"Not Implemented","Partial"))))) -> Partial | O22: =IF(COUNTA(F22:M22)=0,"",(COUNTIF(F22:M22,"Implemented")+COUNTIF(F22:M22,"Partial")+COUNTIF(F22:M22,"Not Implemented"))) -> 3 | P22: =IF(COUNTA(F22:M22)=0,"",COUNTIF(F22:M22,"??")) -> 0 | Q22: =IF(COUNTA(F22:M22)=0,"",COUNTIF(F22:M22,"Partial")+COUNTIF(F22:M22,"Not Implemented")) -> 2 | R22: AA-01: Unique, strong password stored in password manager; not reused elsewhere; recovery email/phone current AA-03: 2-Step Verification method (SMS / app / passkey) AA-05: Third-party apps with Google Account access reviewed and pruned | S22: AA-01: Unique 16+ char password in password manager; recovery contacts verified; backup codes stored offline AA-03: Phishing-resistant MFA (passkey / security key) or authenticator app; SMS removed as a factor AA-05: Unused third-party access removed; reviewed quarterly | T22: The Google Account password is reused across other services but is stored in a password manager. The recovery email is current, but the recovery phone number is outdated. Backup codes have not been saved. Two-Step Verification is enabled with a passkey, and SMS is not used as an authentication factor. Some suspicious or unfamiliar third-party applications were identified, and unused connections have not yet been removed | U22: Password reuse increases the risk of credential stuffing. Outdated recovery information and missing backup codes may complicate account recovery. Unnecessary third-party access may also increase the attack surface. | V22: User confirmed password reuse, password manager use, current recovery email, outdated recovery phone number, no saved backup codes, passkey-based 2-Step Verification, no SMS authentication, and unused or questionable third-party connections. | W22: Change the password to a unique password, update the recovery phone number, generate and securely store backup codes, and remove unused or unfamiliar third-party applications. | X22: F3 | Y22: PR-002, PR-014, PR-023 | Z22: [PR-002] Text also covers other columns: passkey 2-Step Verification with no SMS -> AA-03 looks Implemented; unfamiliar third-party apps not yet removed -> AA-05 looks Partial. Those columns are left as ?? for you to decide.
